<?xml version="1.0" ?>
<!-- =================================================================================== -->
<!-- |    This document was autogenerated by xacro from svh_gazebo-standalone.urdf.xacro | -->
<!-- |    EDITING THIS FILE BY HAND IS NOT RECOMMENDED                                 | -->
<!-- =================================================================================== -->
<robot name="svh" xmlns:xacro="http://www.ros.org/wiki/xacro">
  <!-- All inertia values are dummy values, please change them with the real ones -->
  <link name="interface_plate">
    <inertial>
      <mass value="0.03"/>
      <inertia ixx="0.00001" ixy="0.0" ixz="0.0" iyy="0.00001" iyz="0.0" izz="0.00001"/>
    </inertial>
  </link>
  <!-- RIGHT HAND = 1, LEFT HAND = -1 -->
  <!-- BASE_LINE LINKS -->
  <joint name="right_hand_base_joint" type="fixed">
    <origin rpy="0 0 0" xyz="0 0 0"/>
    <parent link="interface_plate"/>
    <child link="right_hand_base_link"/>
  </joint>
  <link name="right_hand_base_link">
    <inertial>
      <mass value="0.03"/>
      <inertia ixx="0.00001" ixy="0.0" ixz="0.0" iyy="0.00001" iyz="0.0" izz="0.00001"/>
    </inertial>
    <origin rpy="0 0 0" xyz="0 0 0"/>
    <visual>
      <origin rpy="0 0 0" xyz="0 0 -0.032"/>
      <geometry>
        <mesh filename="package://schunk_svh_driver/description/meshes/base10.dae"/>
      </geometry>
    </visual>
    <collision>
      <origin rpy="0 0 0" xyz="0 0 -0.032"/>
      <geometry>
        <mesh filename="package://schunk_svh_driver/description/meshes/base10.dae"/>
      </geometry>
    </collision>
  </link>
  <link name="right_hand_d">
    <inertial>
      <mass value="0.03"/>
      <inertia ixx="0.00001" ixy="0.0" ixz="0.0" iyy="0.00001" iyz="0.0" izz="0.00001"/>
    </inertial>
  </link>
  <link name="right_hand_h">
    <inertial>
      <mass value="0.03"/>
      <inertia ixx="0.00001" ixy="0.0" ixz="0.0" iyy="0.00001" iyz="0.0" izz="0.00001"/>
    </inertial>
  </link>
  <link name="right_hand_d2">
    <inertial>
      <mass value="0.03"/>
      <inertia ixx="0.00001" ixy="0.0" ixz="0.0" iyy="0.00001" iyz="0.0" izz="0.00001"/>
    </inertial>
  </link>
  <!-- LENGTH NOT FOUND IN DATASHEET! GUESSED!!! -->
  <link name="right_hand_e1">
    <inertial>
      <mass value="0.03"/>
      <inertia ixx="0.00001" ixy="0.0" ixz="0.0" iyy="0.00001" iyz="0.0" izz="0.00001"/>
    </inertial>
    <visual>
      <origin rpy="0 0 0" xyz="0 0.01313 0"/>
      <geometry>
        <mesh filename="package://schunk_svh_driver/description/meshes/h10.dae" scale="1 1 1"/>
      </geometry>
    </visual>
    <collision>
      <origin rpy="0 0 0" xyz="0 0.01313 0"/>
      <geometry>
        <mesh filename="package://schunk_svh_driver/description/meshes/h10.dae" scale="1 1 1"/>
      </geometry>
    </collision>
  </link>
  <!-- LENGTH NOT FOUND IN DATASHEET! GUESSED!!! -->
  <link name="right_hand_e2">
    <inertial>
      <mass value="0.03"/>
      <inertia ixx="0.00001" ixy="0.0" ixz="0.0" iyy="0.00001" iyz="0.0" izz="0.00001"/>
    </inertial>
    <visual>
      <origin xyz="-0.0007 0 -0.01002"/>
      <geometry>
        <mesh filename="package://schunk_svh_driver/description/meshes/h11.dae" scale="1 1 1"/>
      </geometry>
    </visual>
    <collision>
      <origin xyz="-0.0007 0 -0.01002"/>
      <geometry>
        <mesh filename="package://schunk_svh_driver/description/meshes/h11.dae" scale="1 1 1"/>
      </geometry>
    </collision>
  </link>
  <!-- LENGTH NOT FOUND IN DATASHEET! GUESSED!!! -->
  <link name="right_hand_e3">
    <inertial>
      <mass value="0.03"/>
      <inertia ixx="0.00001" ixy="0.0" ixz="0.0" iyy="0.00001" iyz="0.0" izz="0.00001"/>
    </inertial>
    <!-- <visual> -->
    <!-- 	<origin rpy="0 0 0" xyz="${side*(0.0175)} 0 0.015" /> -->
    <!-- 	<geometry> -->
    <!-- 	  <cylinder length="0.03" radius="${cyl_radius}" /> -->
    <!-- 	</geometry> -->
    <!-- 	<material name="green" /> -->
    <!-- </visual> -->
  </link>
  <link name="right_hand_e">
    <inertial>
      <mass value="0.03"/>
      <inertia ixx="0.00001" ixy="0.0" ixz="0.0" iyy="0.00001" iyz="0.0" izz="0.00001"/>
    </inertial>
  </link>
  <!-- LENGTH NOT FOUND IN DATASHEET! GUESSED, BUT POSITION CALCULATED: E4 = D-G-F!!! -->
  <link name="right_hand_e4">
    <inertial>
      <mass value="0.03"/>
      <inertia ixx="0.00001" ixy="0.0" ixz="0.0" iyy="0.00001" iyz="0.0" izz="0.00001"/>
    </inertial>
    <!-- <visual> -->
    <!-- 	<origin rpy="0 0 0" xyz="${side*(0.02825)} 0 0.043" /> -->
    <!-- 	<geometry> -->
    <!-- 	  <cylinder length="0.026" radius="${cyl_radius}" /> -->
    <!-- 	</geometry> -->
    <!-- 	<material name="green" /> -->
    <!-- </visual> -->
  </link>
  <!-- LENGTH NOT FOUND IN DATASHEET! GUESSED, BUT POSITION CALCULATED: E5 = D-G!!! -->
  <link name="right_hand_e5">
    <inertial>
      <mass value="0.03"/>
      <inertia ixx="0.00001" ixy="0.0" ixz="0.0" iyy="0.00001" iyz="0.0" izz="0.00001"/>
    </inertial>
    <!-- <visual> -->
    <!-- 	<origin rpy="0 0 0" xyz="${side*(0.00675)} 0 0.04775" /> -->
    <!-- 	<geometry> -->
    <!-- 	  <cylinder length="0.0355" radius="${cyl_radius}" /> -->
    <!-- 	</geometry> -->
    <!-- 	<material name="green" /> -->
    <!-- </visual> -->
  </link>
  <!-- THUMB LINKS -->
  <link name="right_hand_z">
    <inertial>
      <mass value="0.03"/>
      <inertia ixx="0.00001" ixy="0.0" ixz="0.0" iyy="0.00001" iyz="0.0" izz="0.00001"/>
    </inertial>
    <visual>
      <origin xyz="0 0 0.02442"/>
      <geometry>
        <mesh filename="package://schunk_svh_driver/description/meshes/d10.dae" scale="1 1 1"/>
      </geometry>
    </visual>
    <collision>
      <origin xyz="0 0 0.02442"/>
      <geometry>
        <mesh filename="package://schunk_svh_driver/description/meshes/d10.dae" scale="1 1 1"/>
      </geometry>
    </collision>
  </link>
  <link name="right_hand_virtual_a">
    <inertial>
      <mass value="0.03"/>
      <inertia ixx="0.00001" ixy="0.0" ixz="0.0" iyy="0.00001" iyz="0.0" izz="0.00001"/>
    </inertial>
  </link>
  <link name="right_hand_a">
    <inertial>
      <mass value="0.03"/>
      <inertia ixx="0.00001" ixy="0.0" ixz="0.0" iyy="0.00001" iyz="0.0" izz="0.00001"/>
    </inertial>
    <visual>
      <geometry>
        <mesh filename="package://schunk_svh_driver/description/meshes/d11.dae" scale="1 1 1"/>
      </geometry>
    </visual>
    <collision>
      <geometry>
        <mesh filename="package://schunk_svh_driver/description/meshes/d11.dae" scale="1 1 1"/>
      </geometry>
    </collision>
  </link>
  <link name="right_hand_b">
    <inertial>
      <mass value="0.03"/>
      <inertia ixx="0.00001" ixy="0.0" ixz="0.0" iyy="0.00001" iyz="0.0" izz="0.00001"/>
    </inertial>
    <visual>
      <geometry>
        <mesh filename="package://schunk_svh_driver/description/meshes/d12.dae" scale="1 1 1"/>
      </geometry>
    </visual>
    <collision>
      <geometry>
        <mesh filename="package://schunk_svh_driver/description/meshes/d12.dae" scale="1 1 1"/>
      </geometry>
    </collision>
  </link>
  <link name="right_hand_c">
    <inertial>
      <mass value="0.03"/>
      <inertia ixx="0.00001" ixy="0.0" ixz="0.0" iyy="0.00001" iyz="0.0" izz="0.00001"/>
    </inertial>
    <visual>
      <geometry>
        <mesh filename="package://schunk_svh_driver/description/meshes/d13.dae" scale="1 1 1"/>
      </geometry>
    </visual>
    <collision>
      <geometry>
        <mesh filename="package://schunk_svh_driver/description/meshes/d13.dae" scale="1 1 1"/>
      </geometry>
    </collision>
  </link>
  <link name="right_hand_thumb_tip_ee">
        </link>
  <joint name="right_hand_thumb_tip_joint" type="fixed">
    <parent link="right_hand_c"/>
    <child link="right_hand_thumb_tip_ee"/>
    <origin rpy="0 0 0" xyz="0.012 0.01 0.0"/>
  </joint>
  <!-- INDEX FINGER LINKS -->
  <link name="right_hand_virtual_l">
    <inertial>
      <mass value="0.03"/>
      <inertia ixx="0.00001" ixy="0.0" ixz="0.0" iyy="0.00001" iyz="0.0" izz="0.00001"/>
    </inertial>
    <visual>
      <origin xyz="0 0 0.01321"/>
      <geometry>
        <mesh filename="package://schunk_svh_driver/description/meshes/f10.dae"/>
      </geometry>
    </visual>
    <collision>
      <origin xyz="0 0 0.01321"/>
      <geometry>
        <mesh filename="package://schunk_svh_driver/description/meshes/f10.dae"/>
      </geometry>
    </collision>
  </link>
  <link name="right_hand_l">
    <inertial>
      <mass value="0.03"/>
      <inertia ixx="0.00001" ixy="0.0" ixz="0.0" iyy="0.00001" iyz="0.0" izz="0.00001"/>
    </inertial>
    <visual>
      <geometry>
        <mesh filename="package://schunk_svh_driver/description/meshes/f11.dae"/>
      </geometry>
    </visual>
    <collision>
      <geometry>
        <mesh filename="package://schunk_svh_driver/description/meshes/f11.dae"/>
      </geometry>
    </collision>
  </link>
  <link name="right_hand_p">
    <inertial>
      <mass value="0.05"/>
      <origin rpy="0.0 1.57 0.0" xyz="0.0127 0.0 0.0"/>
      <inertia ixx="6.23228917375e-06" ixy="0.0" ixz="0.0" iyy="6.23228917375e-06" iyz="0.0" izz="2.25625e-06"/>
    </inertial>
    <visual>
      <geometry>
        <mesh filename="package://schunk_svh_driver/description/meshes/f12.dae"/>
      </geometry>
    </visual>
    <collision>
      <origin rpy="0 1.57 0" xyz="0.0127 0 0"/>
      <geometry>
        <cylinder length="0.035" radius="0.0095"/>
        <!--mesh filename="package://schunk_svh_driver/description/meshes/f12.dae" /-->
      </geometry>
    </collision>
  </link>
  <link name="right_hand_t">
    <!--xacro:dummy_inertial /-->
    <inertial>
      <mass value="0.03"/>
      <origin rpy="0 1.57 0" xyz="0.007 0 0"/>
      <inertia ixx="2.439999024e-06" ixy="0.0" ixz="0.0" iyy="2.439999024e-06" iyz="0.0" izz="9.6e-07"/>
    </inertial>
    <visual>
      <geometry>
        <mesh filename="package://schunk_svh_driver/description/meshes/f13.dae"/>
      </geometry>
    </visual>
    <collision>
      <origin rpy="0 1.57 0" xyz="0.007 0 0"/>
      <geometry>
        <cylinder length="0.028" radius="0.007"/>
        <!--mesh filename="package://schunk_svh_driver/description/meshes/f13.dae" /-->
      </geometry>
    </collision>
  </link>
  <link name="right_hand_index_tip_ee">
        </link>
  <joint name="right_hand_index_tip_joint" type="fixed">
    <parent link="right_hand_t"/>
    <child link="right_hand_index_tip_ee"/>
    <origin rpy="0 0 0" xyz="0.012 0.007 0.0"/>
  </joint>
  <!-- MIDDLE FINGER LINKS -->
  <link name="right_hand_virtual_k">
    <inertial>
      <mass value="0.03"/>
      <inertia ixx="0.00001" ixy="0.0" ixz="0.0" iyy="0.00001" iyz="0.0" izz="0.00001"/>
    </inertial>
    <visual>
      <origin xyz="0 0 0.01321"/>
      <geometry>
        <mesh filename="package://schunk_svh_driver/description/meshes/f20.dae"/>
      </geometry>
    </visual>
    <collision>
      <origin xyz="0 0 0.01321"/>
      <geometry>
        <mesh filename="package://schunk_svh_driver/description/meshes/f20.dae"/>
      </geometry>
    </collision>
  </link>
  <link name="right_hand_k">
    <inertial>
      <mass value="0.03"/>
      <inertia ixx="0.00001" ixy="0.0" ixz="0.0" iyy="0.00001" iyz="0.0" izz="0.00001"/>
    </inertial>
    <visual>
      <geometry>
        <mesh filename="package://schunk_svh_driver/description/meshes/f21.dae"/>
      </geometry>
    </visual>
    <collision>
      <geometry>
        <mesh filename="package://schunk_svh_driver/description/meshes/f21.dae"/>
      </geometry>
    </collision>
  </link>
  <link name="right_hand_o">
    <!--xacro:dummy_inertial /-->
    <inertial>
      <mass value="0.05"/>
      <origin rpy="0 1.57 0" xyz="0.016 0 0"/>
      <inertia ixx="7.79478854875e-06" ixy="0.0" ixz="0.0" iyy="7.79478854875e-06" iyz="0.0" izz="2.25625e-06"/>
    </inertial>
    <visual>
      <geometry>
        <mesh filename="package://schunk_svh_driver/description/meshes/f22.dae"/>
      </geometry>
    </visual>
    <collision>
      <origin rpy="0 1.57 0" xyz="0.016 0 0"/>
      <geometry>
        <cylinder length="0.04" radius="0.0095"/>
        <!--mesh filename="package://schunk_svh_driver/description/meshes/f22.dae" /-->
      </geometry>
    </collision>
  </link>
  <link name="right_hand_s">
    <!--xacro:dummy_inertial /-->
    <inertial>
      <mass value="0.03"/>
      <origin rpy="0 1.57 0" xyz="0.008 0 0"/>
      <inertia ixx="2.439999024e-06" ixy="0.0" ixz="0.0" iyy="2.439999024e-06" iyz="0.0" izz="9.6e-07"/>
    </inertial>
    <visual>
      <geometry>
        <mesh filename="package://schunk_svh_driver/description/meshes/f23.dae"/>
      </geometry>
    </visual>
    <collision>
      <origin rpy="0 1.57 0" xyz="0.008 0 0"/>
      <geometry>
        <cylinder length="0.028" radius="0.007"/>
        <!--mesh filename="package://schunk_svh_driver/description/meshes/f23.dae" /-->
      </geometry>
    </collision>
  </link>
  <link name="right_hand_middle_tip_ee">
        </link>
  <joint name="right_hand_middle_tip_joint" type="fixed">
    <parent link="right_hand_s"/>
    <child link="right_hand_middle_tip_ee"/>
    <origin rpy="0 0 0" xyz="0.012 0.007 0.0"/>
  </joint>
  <!-- RING FINGER LINKS -->
  <link name="right_hand_virtual_j">
    <inertial>
      <mass value="0.03"/>
      <inertia ixx="0.00001" ixy="0.0" ixz="0.0" iyy="0.00001" iyz="0.0" izz="0.00001"/>
    </inertial>
    <visual>
      <origin xyz="0 0 -0.01321"/>
      <geometry>
        <mesh filename="package://schunk_svh_driver/description/meshes/f30.dae"/>
      </geometry>
    </visual>
    <collision>
      <origin xyz="0 0 -0.01321"/>
      <geometry>
        <mesh filename="package://schunk_svh_driver/description/meshes/f30.dae"/>
      </geometry>
    </collision>
  </link>
  <link name="right_hand_j">
    <inertial>
      <mass value="0.03"/>
      <inertia ixx="0.00001" ixy="0.0" ixz="0.0" iyy="0.00001" iyz="0.0" izz="0.00001"/>
    </inertial>
    <visual>
      <geometry>
        <mesh filename="package://schunk_svh_driver/description/meshes/f31.dae"/>
      </geometry>
    </visual>
    <collision>
      <geometry>
        <mesh filename="package://schunk_svh_driver/description/meshes/f31.dae"/>
      </geometry>
    </collision>
  </link>
  <link name="right_hand_n">
    <inertial>
      <mass value="0.05"/>
      <origin rpy="0 1.57 0" xyz="0.016 0 0"/>
      <inertia ixx="8.47812160875e-06" ixy="0.0" ixz="0.0" iyy="8.47812160875e-06" iyz="0.0" izz="2.25625e-06"/>
    </inertial>
    <visual>
      <geometry>
        <mesh filename="package://schunk_svh_driver/description/meshes/f32.dae"/>
      </geometry>
    </visual>
    <collision>
      <origin rpy="0 1.57 0" xyz="0.016 0 0"/>
      <geometry>
        <cylinder length="0.042" radius="0.0095"/>
        <!--mesh filename="package://schunk_svh_driver/description/meshes/f32.dae" /-->
      </geometry>
    </collision>
  </link>
  <link name="right_hand_r">
    <inertial>
      <mass value="0.03"/>
      <origin rpy="0 1.57 0" xyz="0.008 0 0"/>
      <inertia ixx="2.439999024e-06" ixy="0.0" ixz="0.0" iyy="2.439999024e-06" iyz="0.0" izz="9.6e-07"/>
    </inertial>
    <visual>
      <geometry>
        <mesh filename="package://schunk_svh_driver/description/meshes/f33.dae"/>
      </geometry>
    </visual>
    <collision>
      <origin rpy="0 1.57 0" xyz="0.008 0 0"/>
      <geometry>
        <cylinder length="0.028" radius="0.008"/>
        <!--mesh filename="package://schunk_svh_driver/description/meshes/f33.dae" /-->
      </geometry>
    </collision>
  </link>
  <link name="right_hand_ring_tip_ee">
        </link>
  <joint name="right_hand_ring_tip_joint" type="fixed">
    <parent link="right_hand_r"/>
    <child link="right_hand_ring_tip_ee"/>
    <origin rpy="0 0 0" xyz="0.012 0.007 0.0"/>
  </joint>
  <!-- LITTLE FINGER LINKS -->
  <link name="right_hand_virtual_i">
    <inertial>
      <mass value="0.03"/>
      <inertia ixx="0.00001" ixy="0.0" ixz="0.0" iyy="0.00001" iyz="0.0" izz="0.00001"/>
    </inertial>
    <visual>
      <origin xyz="0 0 -0.01321"/>
      <geometry>
        <mesh filename="package://schunk_svh_driver/description/meshes/f40.dae"/>
      </geometry>
    </visual>
    <collision>
      <origin xyz="0 0 -0.01321"/>
      <geometry>
        <mesh filename="package://schunk_svh_driver/description/meshes/f40.dae"/>
      </geometry>
    </collision>
  </link>
  <link name="right_hand_i">
    <inertial>
      <mass value="0.03"/>
      <inertia ixx="0.00001" ixy="0.0" ixz="0.0" iyy="0.00001" iyz="0.0" izz="0.00001"/>
    </inertial>
    <visual>
      <geometry>
        <mesh filename="package://schunk_svh_driver/description/meshes/f41.dae"/>
      </geometry>
    </visual>
    <collision>
      <geometry>
        <mesh filename="package://schunk_svh_driver/description/meshes/f41.dae"/>
      </geometry>
    </collision>
  </link>
  <link name="right_hand_m">
    <!--xacro:dummy_inertial /-->
    <inertial>
      <mass value="0.05"/>
      <origin rpy="0 1.57 0" xyz="0.016 0 0"/>
      <inertia ixx="5.39478950875e-06" ixy="0.0" ixz="0.0" iyy="5.39478950875e-06" iyz="0.0" izz="2.25625e-06"/>
    </inertial>
    <visual>
      <geometry>
        <mesh filename="package://schunk_svh_driver/description/meshes/f42.dae"/>
      </geometry>
    </visual>
    <collision>
      <origin rpy="0 1.57 0" xyz="0.016 0 0"/>
      <geometry>
        <cylinder length="0.032" radius="0.0095"/>
        <!--mesh filename="package://schunk_svh_driver/description/meshes/f42.dae" /-->
      </geometry>
    </collision>
  </link>
  <link name="right_hand_q">
    <!--xacro:dummy_inertial /-->
    <inertial>
      <mass value="0.03"/>
      <origin rpy="0 1.57 0" xyz="0.008 0 0"/>
      <inertia ixx="2.439999024e-06" ixy="0.0" ixz="0.0" iyy="2.439999024e-06" iyz="0.0" izz="9.6e-07"/>
    </inertial>
    <visual>
      <geometry>
        <mesh filename="package://schunk_svh_driver/description/meshes/f43.dae"/>
      </geometry>
    </visual>
    <collision>
      <origin rpy="0 1.57 0" xyz="0.008 0 0"/>
      <geometry>
        <cylinder length="0.028" radius="0.008"/>
        <!--mesh filename="package://schunk_svh_driver/description/meshes/f43.dae" /-->
      </geometry>
    </collision>
  </link>
  <link name="right_hand_pinky_tip_ee">
        </link>
  <joint name="right_hand_pinky_tip_joint" type="fixed">
    <parent link="right_hand_q"/>
    <child link="right_hand_pinky_tip_ee"/>
    <origin rpy="0 0 0" xyz="0.012 0.007 0.0"/>
  </joint>
  <joint name="right_hand_Thumb_Flexion" type="revolute">
    <parent link="right_hand_virtual_a"/>
    <child link="right_hand_a"/>
    <limit effort="1000.0" lower="0.0" upper="0.9704" velocity="1"/>
    <origin rpy="0 0 -0.9704" xyz="0 0 0"/>
    <axis xyz="0 0 1"/>
  </joint>
  <transmission name="right_hand_Thumb_Flexion_transmission">
    <type>transmission_interface/SimpleTransmission</type>
    <joint name="right_hand_Thumb_Flexion">
      <hardwareInterface>EffortJointInterface</hardwareInterface>
    </joint>
    <actuator name="motor_right_hand_Thumb_Flexion">
      <mechanicalReduction>1</mechanicalReduction>
      <hardwareInterface>EffortJointInterface</hardwareInterface>
    </actuator>
  </transmission>
  <!--transmission name="${name}_Thumb_Flexion_transmission">
            <type>transmission_interface/SimpleTransmission</type>
            <joint name="${name}_Thumb_Flexion">
                <hardwareInterface>EffortJointInterface</hardwareInterface>
            </joint>
            <actuator name="motor_${name}_Thumb_Flexion">
                <mechanicalReduction>1</mechanicalReduction>
                <hardwareInterface>EffortJointInterface</hardwareInterface>
            </actuator>
        </transmission-->
  <joint name="right_hand_Thumb_Helper" type="fixed">
    <!--limit effort="1000" upper="0" lower="0" velocity="1"/-->
    <parent link="right_hand_z"/>
    <child link="right_hand_virtual_a"/>
    <origin rpy="0 -1.5707 3.1416" xyz="0 0 0.04596"/>
  </joint>
  <!-- BASE_LINE JOINTS -->
  <joint name="right_hand_Thumb_Opposition" type="revolute">
    <parent link="right_hand_e1"/>
    <child link="right_hand_z"/>
    <limit effort="1000.0" lower="0.0" upper="0.9879" velocity="1"/>
    <origin rpy="0 0.2618 1.571" xyz="-0.0169 0.02626 0"/>
    <axis xyz="0 0 -1"/>
  </joint>
  <transmission name="right_hand_Thumb_Opposition_transmission">
    <type>transmission_interface/SimpleTransmission</type>
    <joint name="right_hand_Thumb_Opposition">
      <hardwareInterface>EffortJointInterface</hardwareInterface>
    </joint>
    <actuator name="motor_right_hand_Thumb_Opposition">
      <mechanicalReduction>1</mechanicalReduction>
      <hardwareInterface>EffortJointInterface</hardwareInterface>
    </actuator>
  </transmission>
  <!-- JOINT NOT FOR BASE_LINE. BUT WRITTEN DOWN HERE FOR BETTER UX -->
  <joint name="right_hand_f1" type="fixed">
    <!--limit effort="1000" upper="0" lower="0" velocity="1"/-->
    <parent link="right_hand_e1"/>
    <child link="right_hand_d"/>
    <origin rpy="0 0 0" xyz="0 0 0"/>
  </joint>
  <joint name="right_hand_f2" type="fixed">
    <!--limit effort="1000" upper="0" lower="0" velocity="1"/-->
    <parent link="right_hand_d"/>
    <child link="right_hand_h"/>
    <origin rpy="0 0 0" xyz="0 0 0"/>
  </joint>
  <joint name="right_hand_f3" type="fixed">
    <!--limit effort="1000" upper="0" lower="0" velocity="1"/-->
    <parent link="right_hand_h"/>
    <child link="right_hand_d2"/>
    <origin rpy="0 0 0" xyz="0 0 0"/>
  </joint>
  <joint name="right_hand_f4" type="fixed">
    <!--limit effort="1000" upper="0" lower="0" velocity="1"/-->
    <parent link="right_hand_base_link"/>
    <child link="right_hand_e1"/>
    <origin rpy="0 0 0" xyz="0 -0.01313 0"/>
  </joint>
  <joint name="right_hand_j5" type="revolute">
    <parent link="right_hand_e1"/>
    <child link="right_hand_e2"/>
    <limit effort="1000.0" lower="0.0" upper="0.98786" velocity="1"/>
    <origin rpy="0 0 0" xyz="0.0184 0.006 0.0375"/>
    <axis xyz="0 0 1"/>
    <mimic joint="right_hand_Thumb_Opposition" multiplier="1" offset="0"/>
  </joint>
  <transmission name="right_hand_j5_transmission">
    <type>transmission_interface/SimpleTransmission</type>
    <joint name="right_hand_j5">
      <hardwareInterface>EffortJointInterface</hardwareInterface>
    </joint>
    <actuator name="motor_right_hand_j5">
      <mechanicalReduction>1</mechanicalReduction>
      <hardwareInterface>EffortJointInterface</hardwareInterface>
    </actuator>
  </transmission>
  <joint name="right_hand_f5" type="fixed">
    <!--limit effort="1000" upper="0" lower="0" velocity="1"/-->
    <parent link="right_hand_e2"/>
    <child link="right_hand_e3"/>
    <origin rpy="0 0 0" xyz="0 -0.0060 0"/>
  </joint>
  <joint name="right_hand_f6" type="fixed">
    <!--limit effort="1000" upper="0" lower="0" velocity="1"/-->
    <parent link="right_hand_e3"/>
    <child link="right_hand_e"/>
    <origin rpy="0 0 0" xyz="0 0 0"/>
  </joint>
  <joint name="right_hand_f7" type="fixed">
    <!--limit effort="1000" upper="0" lower="0" velocity="1"/-->
    <parent link="right_hand_e"/>
    <child link="right_hand_e4"/>
    <origin rpy="0 0 0" xyz="0 0 0"/>
  </joint>
  <joint name="right_hand_f8" type="fixed">
    <!--limit effort="1000" upper="0" lower="0" velocity="1"/-->
    <parent link="right_hand_e"/>
    <child link="right_hand_e5"/>
    <origin rpy="0 0 0" xyz="0 0 0"/>
  </joint>
  <!-- THUMB JOINTS -->
  <joint name="right_hand_j3" type="revolute">
    <parent link="right_hand_a"/>
    <child link="right_hand_b"/>
    <limit effort="1000.0" lower="0.0" upper="0.98506" velocity="1"/>
    <origin rpy="0 0 0" xyz="0.0485 0 0"/>
    <axis xyz="0 0 1"/>
    <mimic joint="right_hand_Thumb_Flexion" multiplier="1.01511" offset="0"/>
  </joint>
  <transmission name="right_hand_j3_transmission">
    <type>transmission_interface/SimpleTransmission</type>
    <joint name="right_hand_j3">
      <hardwareInterface>EffortJointInterface</hardwareInterface>
    </joint>
    <actuator name="motor_right_hand_j3">
      <mechanicalReduction>1</mechanicalReduction>
      <hardwareInterface>EffortJointInterface</hardwareInterface>
    </actuator>
  </transmission>
  <joint name="right_hand_j4" type="revolute">
    <parent link="right_hand_b"/>
    <child link="right_hand_c"/>
    <limit effort="1000.0" lower="0.0" upper="1.406" velocity="1"/>
    <origin rpy="0 0 0" xyz="0.030 0 0"/>
    <axis xyz="0 0 1"/>
    <mimic joint="right_hand_Thumb_Flexion" multiplier="1.44889" offset="0"/>
  </joint>
  <transmission name="right_hand_j4_transmission">
    <type>transmission_interface/SimpleTransmission</type>
    <joint name="right_hand_j4">
      <hardwareInterface>EffortJointInterface</hardwareInterface>
    </joint>
    <actuator name="motor_right_hand_j4">
      <mechanicalReduction>1</mechanicalReduction>
      <hardwareInterface>EffortJointInterface</hardwareInterface>
    </actuator>
  </transmission>
  <!-- INDEX FINGER JOINTS -->
  <joint name="right_hand_Index_Finger_Distal" type="revolute">
    <parent link="right_hand_l"/>
    <child link="right_hand_p"/>
    <limit effort="1000.0" lower="0" upper="1.334" velocity="1"/>
    <origin rpy="0 0 0" xyz="0.04804 0 0"/>
    <axis xyz="0 0 1"/>
  </joint>
  <transmission name="right_hand_Index_Finger_Distal_transmission">
    <type>transmission_interface/SimpleTransmission</type>
    <joint name="right_hand_Index_Finger_Distal">
      <hardwareInterface>EffortJointInterface</hardwareInterface>
    </joint>
    <actuator name="motor_right_hand_Index_Finger_Distal">
      <mechanicalReduction>1</mechanicalReduction>
      <hardwareInterface>EffortJointInterface</hardwareInterface>
    </actuator>
  </transmission>
  <joint name="right_hand_Index_Finger_Proximal" type="revolute">
    <parent link="right_hand_virtual_l"/>
    <child link="right_hand_l"/>
    <limit effort="1000.0" lower="0.0" upper="0.79849" velocity="1"/>
    <origin rpy="-1.5707 0 0" xyz="0 0 0"/>
    <axis xyz="0 0 1"/>
  </joint>
  <transmission name="right_hand_Index_Finger_Proximal_transmission">
    <type>transmission_interface/SimpleTransmission</type>
    <joint name="right_hand_Index_Finger_Proximal">
      <hardwareInterface>EffortJointInterface</hardwareInterface>
    </joint>
    <actuator name="motor_right_hand_Index_Finger_Proximal">
      <mechanicalReduction>1</mechanicalReduction>
      <hardwareInterface>EffortJointInterface</hardwareInterface>
    </actuator>
  </transmission>
  <!-- JOINT Finger_Spread in BASE_LINE section for better UX -->
  <joint name="right_hand_j14" type="revolute">
    <parent link="right_hand_p"/>
    <child link="right_hand_t"/>
    <limit effort="1000.0" lower="0" upper="1.394" velocity="1"/>
    <origin rpy="0 0 0" xyz="0.026 0 0"/>
    <axis xyz="0 0 1"/>
    <mimic joint="right_hand_Index_Finger_Distal" multiplier="1.0450" offset="0"/>
  </joint>
  <transmission name="right_hand_j14_transmission">
    <type>transmission_interface/SimpleTransmission</type>
    <joint name="right_hand_j14">
      <hardwareInterface>EffortJointInterface</hardwareInterface>
    </joint>
    <actuator name="motor_right_hand_j14">
      <mechanicalReduction>1</mechanicalReduction>
      <hardwareInterface>EffortJointInterface</hardwareInterface>
    </actuator>
  </transmission>
  <!-- MIDDLE FINGER JOINTS -->
  <joint name="right_hand_Middle_Finger_Proximal" type="revolute">
    <parent link="right_hand_virtual_k"/>
    <child link="right_hand_k"/>
    <limit effort="1000.0" lower="0.0" upper="0.79849" velocity="1"/>
    <origin rpy="-1.5707 0 0" xyz="0 0 0"/>
    <axis xyz="0 0 1"/>
  </joint>
  <transmission name="right_hand_Middle_Finger_Proximal_transmission">
    <type>transmission_interface/SimpleTransmission</type>
    <joint name="right_hand_Middle_Finger_Proximal">
      <hardwareInterface>EffortJointInterface</hardwareInterface>
    </joint>
    <actuator name="motor_right_hand_Middle_Finger_Proximal">
      <mechanicalReduction>1</mechanicalReduction>
      <hardwareInterface>EffortJointInterface</hardwareInterface>
    </actuator>
  </transmission>
  <joint name="right_hand_Middle_Finger_Distal" type="revolute">
    <parent link="right_hand_k"/>
    <child link="right_hand_o"/>
    <limit effort="1000.0" lower="0" upper="1.334" velocity="1"/>
    <origin rpy="0 0 0" xyz="0.05004 0 0"/>
    <axis xyz="0 0 1"/>
  </joint>
  <transmission name="right_hand_Middle_Finger_Distal_transmission">
    <type>transmission_interface/SimpleTransmission</type>
    <joint name="right_hand_Middle_Finger_Distal">
      <hardwareInterface>EffortJointInterface</hardwareInterface>
    </joint>
    <actuator name="motor_right_hand_Middle_Finger_Distal">
      <mechanicalReduction>1</mechanicalReduction>
      <hardwareInterface>EffortJointInterface</hardwareInterface>
    </actuator>
  </transmission>
  <joint name="right_hand_j15" type="revolute">
    <parent link="right_hand_o"/>
    <child link="right_hand_s"/>
    <limit effort="1000.0" lower="0" upper="1.334" velocity="1"/>
    <origin rpy="0 0 0" xyz="0.032 0 0"/>
    <axis xyz="0 0 1"/>
    <mimic joint="right_hand_Middle_Finger_Distal" multiplier="1.0454" offset="0"/>
  </joint>
  <transmission name="right_hand_j15_transmission">
    <type>transmission_interface/SimpleTransmission</type>
    <joint name="right_hand_j15">
      <hardwareInterface>EffortJointInterface</hardwareInterface>
    </joint>
    <actuator name="motor_right_hand_j15">
      <mechanicalReduction>1</mechanicalReduction>
      <hardwareInterface>EffortJointInterface</hardwareInterface>
    </actuator>
  </transmission>
  <!-- RING FINGER JOINTS -->
  <joint name="right_hand_Ring_Finger" type="revolute">
    <parent link="right_hand_virtual_j"/>
    <child link="right_hand_j"/>
    <limit effort="1000.0" lower="0.0" upper="0.98175" velocity="1"/>
    <origin rpy="1.5707 0 0" xyz="0 0 0"/>
    <axis xyz="0 0 1"/>
  </joint>
  <transmission name="right_hand_Ring_Finger_transmission">
    <type>transmission_interface/SimpleTransmission</type>
    <joint name="right_hand_Ring_Finger">
      <hardwareInterface>EffortJointInterface</hardwareInterface>
    </joint>
    <actuator name="motor_right_hand_Ring_Finger">
      <mechanicalReduction>1</mechanicalReduction>
      <hardwareInterface>EffortJointInterface</hardwareInterface>
    </actuator>
  </transmission>
  <joint name="right_hand_j12" type="revolute">
    <parent link="right_hand_j"/>
    <child link="right_hand_n"/>
    <limit effort="1000.0" lower="0" upper="1.334" velocity="1"/>
    <origin rpy="0 0 0" xyz="0.05004 0 0"/>
    <axis xyz="0 0 1"/>
    <mimic joint="right_hand_Ring_Finger" multiplier="1.3588" offset="0"/>
  </joint>
  <transmission name="right_hand_j12_transmission">
    <type>transmission_interface/SimpleTransmission</type>
    <joint name="right_hand_j12">
      <hardwareInterface>EffortJointInterface</hardwareInterface>
    </joint>
    <actuator name="motor_right_hand_j12">
      <mechanicalReduction>1</mechanicalReduction>
      <hardwareInterface>EffortJointInterface</hardwareInterface>
    </actuator>
  </transmission>
  <joint name="right_hand_j16" type="revolute">
    <parent link="right_hand_n"/>
    <child link="right_hand_r"/>
    <limit effort="1000.0" lower="0" upper="1.395" velocity="1"/>
    <origin rpy="0 0 0" xyz="0.032 0 0"/>
    <axis xyz="0 0 1"/>
    <mimic joint="right_hand_Ring_Finger" multiplier="1.42093" offset="0"/>
  </joint>
  <transmission name="right_hand_j16_transmission">
    <type>transmission_interface/SimpleTransmission</type>
    <joint name="right_hand_j16">
      <hardwareInterface>EffortJointInterface</hardwareInterface>
    </joint>
    <actuator name="motor_right_hand_j16">
      <mechanicalReduction>1</mechanicalReduction>
      <hardwareInterface>EffortJointInterface</hardwareInterface>
    </actuator>
  </transmission>
  <!-- PINKY JOINTS -->
  <joint name="right_hand_Pinky" type="revolute">
    <parent link="right_hand_virtual_i"/>
    <child link="right_hand_i"/>
    <limit effort="1000.0" lower="0.0" upper="0.98175" velocity="1"/>
    <origin rpy="1.5707 0 0" xyz="0 0 0"/>
    <axis xyz="0 0 1"/>
  </joint>
  <transmission name="right_hand_Pinky_transmission">
    <type>transmission_interface/SimpleTransmission</type>
    <joint name="right_hand_Pinky">
      <hardwareInterface>EffortJointInterface</hardwareInterface>
    </joint>
    <actuator name="motor_right_hand_Pinky">
      <mechanicalReduction>1</mechanicalReduction>
      <hardwareInterface>EffortJointInterface</hardwareInterface>
    </actuator>
  </transmission>
  <joint name="right_hand_j13" type="revolute">
    <parent link="right_hand_i"/>
    <child link="right_hand_m"/>
    <limit effort="1000.0" lower="0" upper="1.334" velocity="1"/>
    <origin rpy="0 0 0" xyz="0.04454 0 0"/>
    <axis xyz="0 0 1"/>
    <mimic joint="right_hand_Pinky" multiplier="1.35880" offset="0"/>
  </joint>
  <transmission name="right_hand_j13_transmission">
    <type>transmission_interface/SimpleTransmission</type>
    <joint name="right_hand_j13">
      <hardwareInterface>EffortJointInterface</hardwareInterface>
    </joint>
    <actuator name="motor_right_hand_j13">
      <mechanicalReduction>1</mechanicalReduction>
      <hardwareInterface>EffortJointInterface</hardwareInterface>
    </actuator>
  </transmission>
  <joint name="right_hand_j17" type="revolute">
    <parent link="right_hand_m"/>
    <child link="right_hand_q"/>
    <limit effort="1000.0" lower="0" upper="1.3971" velocity="1"/>
    <origin rpy="0 0 0" xyz="0.022 0 0"/>
    <axis xyz="0 0 1"/>
    <mimic joint="right_hand_Pinky" multiplier="1.42307" offset="0"/>
  </joint>
  <transmission name="right_hand_j17_transmission">
    <type>transmission_interface/SimpleTransmission</type>
    <joint name="right_hand_j17">
      <hardwareInterface>EffortJointInterface</hardwareInterface>
    </joint>
    <actuator name="motor_right_hand_j17">
      <mechanicalReduction>1</mechanicalReduction>
      <hardwareInterface>EffortJointInterface</hardwareInterface>
    </actuator>
  </transmission>
  <joint name="right_hand_index_spread" type="revolute">
    <parent link="right_hand_d2"/>
    <child link="right_hand_virtual_l"/>
    <limit effort="1000.0" lower="0.0" upper="0.28833" velocity="1"/>
    <origin rpy="0 -1.5707 1.5707" xyz="-0.025 0 0.110"/>
    <axis xyz="0 0 1"/>
    <mimic joint="right_hand_Finger_Spread" multiplier="0.5" offset="0"/>
  </joint>
  <transmission name="right_hand_index_spread_transmission">
    <type>transmission_interface/SimpleTransmission</type>
    <joint name="right_hand_index_spread">
      <hardwareInterface>EffortJointInterface</hardwareInterface>
    </joint>
    <actuator name="motor_right_hand_index_spread">
      <mechanicalReduction>1</mechanicalReduction>
      <hardwareInterface>EffortJointInterface</hardwareInterface>
    </actuator>
  </transmission>
  <joint name="right_hand_middle_spread_dummy" type="fixed">
    <!--limit effort="1000" upper="0" lower="0" velocity="1"/-->
    <parent link="right_hand_d"/>
    <child link="right_hand_virtual_k"/>
    <origin rpy="0 -1.5707 1.5707" xyz="0 0 0.110"/>
  </joint>
  <joint name="right_hand_ring_spread" type="revolute">
    <parent link="right_hand_e5"/>
    <child link="right_hand_virtual_j"/>
    <limit effort="1000.0" lower="0.0" upper="0.28833" velocity="1"/>
    <origin rpy="-1.5707 -1.5707 0" xyz="0.003855 0 0.0655"/>
    <axis xyz="0 0 1"/>
    <mimic joint="right_hand_Finger_Spread" multiplier="0.5" offset="0"/>
  </joint>
  <transmission name="right_hand_ring_spread_transmission">
    <type>transmission_interface/SimpleTransmission</type>
    <joint name="right_hand_ring_spread">
      <hardwareInterface>EffortJointInterface</hardwareInterface>
    </joint>
    <actuator name="motor_right_hand_ring_spread">
      <mechanicalReduction>1</mechanicalReduction>
      <hardwareInterface>EffortJointInterface</hardwareInterface>
    </actuator>
  </transmission>
  <joint name="right_hand_Finger_Spread" type="revolute">
    <parent link="right_hand_e4"/>
    <child link="right_hand_virtual_i"/>
    <limit effort="1000.0" lower="0.00" upper="0.5829" velocity="1"/>
    <origin rpy="-1.5707 -1.5707 0" xyz="0.025355 0 0.056"/>
    <axis xyz="0 0 1"/>
  </joint>
  <transmission name="right_hand_Finger_Spread_transmission">
    <type>transmission_interface/SimpleTransmission</type>
    <joint name="right_hand_Finger_Spread">
      <hardwareInterface>EffortJointInterface</hardwareInterface>
    </joint>
    <actuator name="motor_right_hand_Finger_Spread">
      <mechanicalReduction>1</mechanicalReduction>
      <hardwareInterface>EffortJointInterface</hardwareInterface>
    </actuator>
  </transmission>
  <gazebo reference="right_hand_c">
    <!--material>Gazebo/Blue</material-->
    <mu1>0.70</mu1>
    <mu2>0.70</mu2>
    <minDepth>0.001</minDepth>
    <maxVel>0.1</maxVel>
    <kp>10000000.0</kp>
    <kd>100000.0</kd>
  </gazebo>
  <gazebo reference="right_hand_b">
    <!--material>Gazebo/Blue</material-->
    <mu1>0.70</mu1>
    <mu2>0.70</mu2>
    <minDepth>0.001</minDepth>
    <maxVel>0.1</maxVel>
    <kp>10000000.0</kp>
    <kd>100000.0</kd>
  </gazebo>
  <gazebo reference="right_hand_a">
    <!--material>Gazebo/Blue</material-->
    <mu1>0.70</mu1>
    <mu2>0.70</mu2>
    <minDepth>0.001</minDepth>
    <maxVel>0.1</maxVel>
    <kp>10000000.0</kp>
    <kd>100000.0</kd>
  </gazebo>
  <gazebo reference="right_hand_t">
    <!--material>Gazebo/Blue</material-->
    <mu1>0.70</mu1>
    <mu2>0.70</mu2>
    <minDepth>0.001</minDepth>
    <maxVel>0.1</maxVel>
    <kp>10000000.0</kp>
    <kd>100000.0</kd>
  </gazebo>
  <gazebo reference="right_hand_p">
    <!--material>Gazebo/Blue</material-->
    <mu1>0.70</mu1>
    <mu2>0.70</mu2>
    <minDepth>0.001</minDepth>
    <maxVel>0.1</maxVel>
    <kp>10000000.0</kp>
    <kd>100000.0</kd>
  </gazebo>
  <gazebo reference="right_hand_l">
    <!--material>Gazebo/Blue</material-->
    <mu1>0.70</mu1>
    <mu2>0.70</mu2>
    <minDepth>0.001</minDepth>
    <maxVel>0.1</maxVel>
    <kp>10000000.0</kp>
    <kd>100000.0</kd>
  </gazebo>
  <gazebo reference="right_hand_s">
    <!--material>Gazebo/Blue</material-->
    <mu1>0.70</mu1>
    <mu2>0.70</mu2>
    <minDepth>0.001</minDepth>
    <maxVel>0.1</maxVel>
    <kp>10000000.0</kp>
    <kd>100000.0</kd>
  </gazebo>
  <gazebo reference="right_hand_o">
    <!--material>Gazebo/Blue</material-->
    <mu1>0.70</mu1>
    <mu2>0.70</mu2>
    <minDepth>0.001</minDepth>
    <maxVel>0.1</maxVel>
    <kp>10000000.0</kp>
    <kd>100000.0</kd>
  </gazebo>
  <gazebo reference="right_hand_k">
    <!--material>Gazebo/Blue</material-->
    <mu1>0.70</mu1>
    <mu2>0.70</mu2>
    <minDepth>0.001</minDepth>
    <maxVel>0.1</maxVel>
    <kp>10000000.0</kp>
    <kd>100000.0</kd>
  </gazebo>
  <gazebo reference="right_hand_r">
    <!--material>Gazebo/Blue</material-->
    <mu1>0.70</mu1>
    <mu2>0.70</mu2>
    <minDepth>0.001</minDepth>
    <maxVel>0.1</maxVel>
    <kp>10000000.0</kp>
    <kd>100000.0</kd>
  </gazebo>
  <gazebo reference="right_hand_n">
    <!--material>Gazebo/Blue</material-->
    <mu1>0.70</mu1>
    <mu2>0.70</mu2>
    <minDepth>0.001</minDepth>
    <maxVel>0.1</maxVel>
    <kp>10000000.0</kp>
    <kd>100000.0</kd>
  </gazebo>
  <gazebo reference="right_hand_j">
    <!--material>Gazebo/Blue</material-->
    <mu1>0.70</mu1>
    <mu2>0.70</mu2>
    <minDepth>0.001</minDepth>
    <maxVel>0.1</maxVel>
    <kp>10000000.0</kp>
    <kd>100000.0</kd>
  </gazebo>
  <gazebo reference="right_hand_q">
    <!--material>Gazebo/Blue</material-->
    <mu1>0.70</mu1>
    <mu2>0.70</mu2>
    <minDepth>0.001</minDepth>
    <maxVel>0.1</maxVel>
    <kp>10000000.0</kp>
    <kd>100000.0</kd>
  </gazebo>
  <gazebo reference="right_hand_m">
    <!--material>Gazebo/Blue</material-->
    <mu1>0.70</mu1>
    <mu2>0.70</mu2>
    <minDepth>0.001</minDepth>
    <maxVel>0.1</maxVel>
    <kp>10000000.0</kp>
    <kd>100000.0</kd>
  </gazebo>
  <gazebo reference="right_hand_i">
    <!--material>Gazebo/Blue</material-->
    <mu1>0.70</mu1>
    <mu2>0.70</mu2>
    <minDepth>0.001</minDepth>
    <maxVel>0.1</maxVel>
    <kp>10000000.0</kp>
    <kd>100000.0</kd>
  </gazebo>
  <gazebo reference="right_hand_d">
    <!--material>Gazebo/Blue</material-->
    <mu1>0.70</mu1>
    <mu2>0.70</mu2>
    <minDepth>0.001</minDepth>
    <maxVel>0.1</maxVel>
    <kp>10000000.0</kp>
    <kd>100000.0</kd>
  </gazebo>
  <!-- Gazebo configuration -->
  <gazebo>
    <plugin filename="libgazebo_ros_control.so" name="gazebo_ros_control">
      <robotNamespace>/svh</robotNamespace>
      <robotParam>robot_description_gazebo</robotParam>
    </plugin>
  </gazebo>
  <gazebo reference="base_link">
    <material>Gazebo/Blue</material>
  </gazebo>
  <gazebo reference="interface_plate">
    <static>true</static>
    <gravity>false</gravity>
  </gazebo>
  <gazebo reference="svh">
    <static>true</static>
    <gravity>false</gravity>
  </gazebo>
  <!--xacro:if value="$(arg load_grasp_fix)">
        <xacro:include filename="$(find schunk_svh_gazebo)/desciption/gzplugin_grasp_fix_schunk_standalone.xacro"/>
        <xacro:gzplugin_grasp_fix/>
    </xacro:if-->
</robot>

