<?xml version="1.0"?>
<robot name="svh" xmlns:xacro="http://www.ros.org/wiki/xacro">

    <!-- All inertia values are dummy values, please change them with the real ones -->


    <xacro:property name="cyl_radius" value="0.001" />

    <xacro:macro name="cylinder_inertial" params="radius length mass *origin">
        <inertial>
            <mass value="${mass}" />
            <insert_block name="origin" />
            <inertia ixx="${0.0833333 * mass * (3 * radius * radius + length * length)}" ixy="0.0" ixz="0.0"
                iyy="${0.0833333 * mass * (3 * radius * radius + length * length)}" iyz="0.0"
                izz="${0.5 * mass * radius * radius}" />
        </inertial>
    </xacro:macro>

    <xacro:macro name="dummy_inertial">
        <inertial>
            <mass value="0.03" />
            <inertia ixx="0.00001" ixy="0.0" ixz="0.0"
                iyy="0.00001" iyz="0.0"
                izz="0.00001" />
        </inertial>
    </xacro:macro>
    
    <xacro:macro name="trans_xacro" params="namehand jointname">
        <transmission name="${namehand}_${jointname}_transmission">
            <type>transmission_interface/SimpleTransmission</type>
            <joint name="${namehand}_${jointname}">
                <hardwareInterface>EffortJointInterface</hardwareInterface>
            </joint>
            <actuator name="motor_${namehand}_${jointname}">
                <mechanicalReduction>1</mechanicalReduction>
                <hardwareInterface>EffortJointInterface</hardwareInterface>
            </actuator>
        </transmission>
    </xacro:macro>

    <xacro:macro name="tip_ee" params="name parent xyz">
        <link name="${name}_tip_ee">
        </link>

        <joint name="${name}_tip_joint" type="fixed">
            <parent link="${parent}" />
            <child link="${name}_tip_ee" />
            <origin xyz="${xyz}" rpy="0 0 0" />
        </joint>
    </xacro:macro>

    <xacro:macro name="gazebo_contact" params="link_name">
        <gazebo reference="${link_name}">                                                                            
            <!--material>Gazebo/Blue</material-->                                                                      
            <mu1>0.70</mu1>
            <mu2>0.70</mu2>

            <minDepth>0.001</minDepth>
            <maxVel>0.1</maxVel>

            <kp>10000000.0</kp>
            <kd>100000.0</kd>
        </gazebo>                         
    </xacro:macro>


    <xacro:macro name="svh" params="parent name side *origin">
        <!-- RIGHT HAND = 1, LEFT HAND = -1 -->
        <!-- BASE_LINE LINKS -->

        <joint name="${name}_base_joint" type="fixed" >
            <insert_block name="origin" />
            <parent link="${parent}" />
            <child link="${name}_base_link" />
        </joint>

        <link name="${name}_base_link">
            <xacro:dummy_inertial />
            <xacro:insert_block name="origin" />
            
            <visual>
                <origin xyz="0 0 -0.032" rpy="0 0 0" />
                <geometry>
                    <mesh filename="package://schunk_svh_driver/description/meshes/base10.dae" />
                </geometry>
            </visual>
            <collision>
                <origin xyz="0 0 -0.032" rpy="0 0 0" />
                <geometry>
                    <mesh filename="package://schunk_svh_driver/description/meshes/base10.dae" />
                </geometry>
            </collision>
        </link>

        <link name="${name}_d">
            <xacro:dummy_inertial />
        </link>

        <link name="${name}_h">
            <xacro:dummy_inertial />
        </link>

        <link name="${name}_d2">
            <xacro:dummy_inertial />
        </link>

        <!-- LENGTH NOT FOUND IN DATASHEET! GUESSED!!! -->
        <link name="${name}_e1">
            <xacro:dummy_inertial />
            <visual>
                <origin rpy="0 0 0" xyz="0 0.01313 0" />
                <geometry>
                    <mesh scale="${side*(1)} 1 1" filename="package://schunk_svh_driver/description/meshes/h10.dae" />
                </geometry>
            </visual>
            <collision>
                <origin rpy="0 0 0" xyz="0 0.01313 0" />
                <geometry>
                    <mesh scale="${side*(1)} 1 1" filename="package://schunk_svh_driver/description/meshes/h10.dae" />
                </geometry>
            </collision>
        </link>

        <!-- LENGTH NOT FOUND IN DATASHEET! GUESSED!!! -->
        <link name="${name}_e2">
            <xacro:dummy_inertial />
            <visual>
                <origin xyz="${side*(-0.0007)} 0 -0.01002" />
                <geometry>
                    <mesh scale="${side*(1)} 1 1" filename="package://schunk_svh_driver/description/meshes/h11.dae" />
                </geometry>
            </visual>
            <collision>
                <origin xyz="${side*(-0.0007)} 0 -0.01002" />
                <geometry>
                    <mesh scale="${side*(1)} 1 1" filename="package://schunk_svh_driver/description/meshes/h11.dae" />
                </geometry>
            </collision>
        </link>

        <!-- LENGTH NOT FOUND IN DATASHEET! GUESSED!!! -->
        <link name="${name}_e3">
            <xacro:dummy_inertial />
            <!-- <visual> -->
                <!-- 	<origin rpy="0 0 0" xyz="${side*(0.0175)} 0 0.015" /> -->
                <!-- 	<geometry> -->
                    <!-- 	  <cylinder length="0.03" radius="${cyl_radius}" /> -->
                    <!-- 	</geometry> -->
                <!-- 	<material name="green" /> -->
                <!-- </visual> -->
        </link>

        <link name="${name}_e">
            <xacro:dummy_inertial />
        </link>

        <!-- LENGTH NOT FOUND IN DATASHEET! GUESSED, BUT POSITION CALCULATED: E4 = D-G-F!!! -->
        <link name="${name}_e4">
            <xacro:dummy_inertial />
            <!-- <visual> -->
                <!-- 	<origin rpy="0 0 0" xyz="${side*(0.02825)} 0 0.043" /> -->
                <!-- 	<geometry> -->
                    <!-- 	  <cylinder length="0.026" radius="${cyl_radius}" /> -->
                    <!-- 	</geometry> -->
                <!-- 	<material name="green" /> -->
                <!-- </visual> -->
        </link>

        <!-- LENGTH NOT FOUND IN DATASHEET! GUESSED, BUT POSITION CALCULATED: E5 = D-G!!! -->
        <link name="${name}_e5">
            <xacro:dummy_inertial />
            <!-- <visual> -->
                <!-- 	<origin rpy="0 0 0" xyz="${side*(0.00675)} 0 0.04775" /> -->
                <!-- 	<geometry> -->
                    <!-- 	  <cylinder length="0.0355" radius="${cyl_radius}" /> -->
                    <!-- 	</geometry> -->
                <!-- 	<material name="green" /> -->
                <!-- </visual> -->
        </link>


        <!-- THUMB LINKS -->
        <link name="${name}_z">
            <xacro:dummy_inertial />
            <visual>
                <origin xyz="0 0 0.02442" />
                <geometry>
                    <mesh scale="1 ${side*(1)} 1" filename="package://schunk_svh_driver/description/meshes/d10.dae" />
                </geometry>
            </visual>
            <collision>
                <origin xyz="0 0 0.02442" />
                <geometry>
                    <mesh scale="1 ${side*(1)} 1" filename="package://schunk_svh_driver/description/meshes/d10.dae" />
                </geometry>
            </collision>
        </link>

        <link name="${name}_virtual_a" >
            <xacro:dummy_inertial />
        </link>
        <link name="${name}_a">
            <xacro:dummy_inertial />
            <visual>
                <geometry>
                    <mesh scale="1 ${side*(1)} ${side*(1)}" filename="package://schunk_svh_driver/description/meshes/d11.dae" />
                </geometry>
            </visual>
            <collision>
                <geometry>
                    <mesh scale="1 ${side*(1)} ${side*(1)}" filename="package://schunk_svh_driver/description/meshes/d11.dae" />
                </geometry>
            </collision>
        </link>

        <link name="${name}_b">
            <xacro:dummy_inertial />
  
            <visual>
                <geometry>
                    <mesh scale="1 ${side*(1)} ${side*(1)}" filename="package://schunk_svh_driver/description/meshes/d12.dae" />
                </geometry>
            </visual>
            <collision>
                <geometry>
                    <mesh scale="1 ${side*(1)} ${side*(1)}" filename="package://schunk_svh_driver/description/meshes/d12.dae" />
                </geometry>
            </collision>
        </link>

        <link name="${name}_c">
            <xacro:dummy_inertial />

            <visual>
                <geometry>
                    <mesh scale="1 ${side*(1)} ${side*(1)}" filename="package://schunk_svh_driver/description/meshes/d13.dae" />
                </geometry>
            </visual>
            <collision>
                <geometry>
                    <mesh scale="1 ${side*(1)} ${side*(1)}" filename="package://schunk_svh_driver/description/meshes/d13.dae" />
                </geometry>
            </collision>
        </link>

        <!-- Tip link and joint  -->
        <xacro:tip_ee name="${name}_thumb" parent="${name}_c" xyz="0.012 0.01 0.0"/>

        <!-- INDEX FINGER LINKS -->
        <link name="${name}_virtual_l">
            <xacro:dummy_inertial />

            <visual>
                <origin xyz="0 0 0.01321" />
                <geometry>
                    <mesh filename="package://schunk_svh_driver/description/meshes/f10.dae" />
                </geometry>
            </visual>
            <collision>
                <origin xyz="0 0 0.01321" />
                <geometry>
                    <mesh filename="package://schunk_svh_driver/description/meshes/f10.dae" />
                </geometry>
            </collision>
        </link>

        <link name="${name}_l">
            <xacro:dummy_inertial />

            <visual>
                <geometry>
                    <mesh filename="package://schunk_svh_driver/description/meshes/f11.dae" />
                </geometry>
            </visual>
            <collision>
                <geometry>
                    <mesh filename="package://schunk_svh_driver/description/meshes/f11.dae" />
                </geometry>
            </collision>
        </link>

        <link name="${name}_p">
            <xacro:cylinder_inertial radius="0.0095" length="0.035" mass="0.05">
                <origin xyz="0.0127 0.0 0.0" rpy="0.0 1.57 0.0" />
            </xacro:cylinder_inertial>
            <visual>
                <geometry>
                    <mesh filename="package://schunk_svh_driver/description/meshes/f12.dae" />
                </geometry>
            </visual>
            <collision>
                <origin xyz="0.0127 0 0" rpy="0 1.57 0" />
                <geometry>
                    <cylinder length="0.035" radius="0.0095" />
                    <!--mesh filename="package://schunk_svh_driver/description/meshes/f12.dae" /-->
                </geometry>
            </collision>
        </link>

        <link name="${name}_t">
            <!--xacro:dummy_inertial /-->

            <xacro:cylinder_inertial radius="0.008" length="0.028" mass="0.03">
                <origin xyz="0.007 0 0" rpy="0 1.57 0" />
            </xacro:cylinder_inertial>
            <visual>
                <geometry>
                    <mesh filename="package://schunk_svh_driver/description/meshes/f13.dae" />
                </geometry>
            </visual>
            <collision>
                <origin xyz="0.007 0 0" rpy="0 1.57 0" />
                <geometry>
                    <cylinder length="0.028" radius="0.007" />
                    <!--mesh filename="package://schunk_svh_driver/description/meshes/f13.dae" /-->
                </geometry>
            </collision>
        </link>

        <!-- Tip link and joint  -->
        <xacro:tip_ee name="${name}_index" parent="${name}_t" xyz="0.012 0.007 0.0"/>

        <!-- MIDDLE FINGER LINKS -->
        <link name="${name}_virtual_k">
            <xacro:dummy_inertial />

            <visual>
                <origin xyz="0 0 0.01321" />
                <geometry>
                    <mesh filename="package://schunk_svh_driver/description/meshes/f20.dae" />
                </geometry>
            </visual>
            <collision>
                <origin xyz="0 0 0.01321" />
                <geometry>
                    <mesh filename="package://schunk_svh_driver/description/meshes/f20.dae" />
                </geometry>
            </collision>
        </link>

        <link name="${name}_k">
            <xacro:dummy_inertial />

            <visual>
                <geometry>
                    <mesh filename="package://schunk_svh_driver/description/meshes/f21.dae" />
                </geometry>
            </visual>
            <collision>
                <geometry>
                    <mesh filename="package://schunk_svh_driver/description/meshes/f21.dae" />
                </geometry>
            </collision>
        </link>

        <link name="${name}_o">
            <!--xacro:dummy_inertial /-->

            <xacro:cylinder_inertial radius="0.0095" length="0.04" mass="0.05">
                <origin xyz="0.016 0 0" rpy="0 1.57 0" />
            </xacro:cylinder_inertial>

            <visual>
                <geometry>
                    <mesh filename="package://schunk_svh_driver/description/meshes/f22.dae" />
                </geometry>
            </visual>
            <collision>
                <origin xyz="0.016 0 0" rpy="0 1.57 0" />
                <geometry>
                    <cylinder length="0.04" radius="0.0095" />
                    <!--mesh filename="package://schunk_svh_driver/description/meshes/f22.dae" /-->
                </geometry>
            </collision>
        </link>

        <link name="${name}_s">
            <!--xacro:dummy_inertial /-->

            <xacro:cylinder_inertial radius="0.008" length="0.028" mass="0.03">
                <origin xyz="0.008 0 0" rpy="0 1.57 0" />
            </xacro:cylinder_inertial>
            <visual>
                <geometry>
                    <mesh filename="package://schunk_svh_driver/description/meshes/f23.dae" />
                </geometry>
            </visual>
            <collision>
                <origin xyz="0.008 0 0" rpy="0 1.57 0" />
                <geometry>
                    <cylinder length="0.028" radius="0.007" />
                    <!--mesh filename="package://schunk_svh_driver/description/meshes/f23.dae" /-->
                </geometry>
            </collision>
        </link>

        <!-- Tip link and joint  -->
        <xacro:tip_ee name="${name}_middle" parent="${name}_s" xyz="0.012 0.007 0.0"/>

        <!-- RING FINGER LINKS -->
        <link name="${name}_virtual_j">
            <xacro:dummy_inertial />

            <visual>
                <origin xyz="0 0 -0.01321" />
                <geometry>
                    <mesh filename="package://schunk_svh_driver/description/meshes/f30.dae" />
                </geometry>
            </visual>
            <collision>
                <origin xyz="0 0 -0.01321" />
                <geometry>
                    <mesh filename="package://schunk_svh_driver/description/meshes/f30.dae" />
                </geometry>
            </collision>
        </link>

        <link name="${name}_j">
            <xacro:dummy_inertial />

            <visual>
                <geometry>
                    <mesh filename="package://schunk_svh_driver/description/meshes/f31.dae" />
                </geometry>
            </visual>
            <collision>
                <geometry>
                    <mesh filename="package://schunk_svh_driver/description/meshes/f31.dae" />
                </geometry>
            </collision>
        </link>

        <link name="${name}_n">
            <!--xacro:dummy_inertial /-->
            <xacro:cylinder_inertial radius="0.0095" length="0.042" mass="0.05">
                <origin xyz="0.016 0 0" rpy="0 1.57 0" />
            </xacro:cylinder_inertial>

            <visual>
                <geometry>
                    <mesh filename="package://schunk_svh_driver/description/meshes/f32.dae" />
                </geometry>
            </visual>
            <collision>
                <origin xyz="0.016 0 0" rpy="0 1.57 0" />
                <geometry>
                    <cylinder length="0.042" radius="0.0095" />
                    <!--mesh filename="package://schunk_svh_driver/description/meshes/f32.dae" /-->
                </geometry>
            </collision>
        </link>

        <link name="${name}_r">
            <!--xacro:dummy_inertial /-->
            <xacro:cylinder_inertial radius="0.008" length="0.028" mass="0.03">
                <origin xyz="0.008 0 0" rpy="0 1.57 0" />
            </xacro:cylinder_inertial>
            <visual>
                <geometry>
                    <mesh filename="package://schunk_svh_driver/description/meshes/f33.dae" />
                </geometry>
            </visual>
            <collision>
                <origin xyz="0.008 0 0" rpy="0 1.57 0" />
                <geometry>
                    <cylinder length="0.028" radius="0.008" />
                    <!--mesh filename="package://schunk_svh_driver/description/meshes/f33.dae" /-->
                </geometry>
            </collision>
        </link>

        <!-- Tip link and joint  -->
        <xacro:tip_ee name="${name}_ring" parent="${name}_r" xyz="0.012 0.007 0.0"/>

        <!-- LITTLE FINGER LINKS -->
        <link name="${name}_virtual_i">
            <xacro:dummy_inertial />

            <visual>
                <origin xyz="0 0 -0.01321" />
                <geometry>
                    <mesh filename="package://schunk_svh_driver/description/meshes/f40.dae" />
                </geometry>
            </visual>
            <collision>
                <origin xyz="0 0 -0.01321" />
                <geometry>
                    <mesh filename="package://schunk_svh_driver/description/meshes/f40.dae" />
                </geometry>
            </collision>
        </link>

        <link name="${name}_i">
            <xacro:dummy_inertial />

            <visual>
                <geometry>
                    <mesh filename="package://schunk_svh_driver/description/meshes/f41.dae" />
                </geometry>
            </visual>
            <collision>
                <geometry>
                    <mesh filename="package://schunk_svh_driver/description/meshes/f41.dae" />
                </geometry>
            </collision>
        </link>

        <link name="${name}_m">
            <!--xacro:dummy_inertial /-->

            <xacro:cylinder_inertial radius="0.0095" length="0.032" mass="0.05">
                <origin xyz="0.016 0 0" rpy="0 1.57 0" />
            </xacro:cylinder_inertial>

            <visual>
                <geometry>
                    <mesh filename="package://schunk_svh_driver/description/meshes/f42.dae" />
                </geometry>
            </visual>
            <collision>
                <origin xyz="0.016 0 0" rpy="0 1.57 0" />
                <geometry>
                    <cylinder length="0.032" radius="0.0095" />
                    <!--mesh filename="package://schunk_svh_driver/description/meshes/f42.dae" /-->
                </geometry>
            </collision>
        </link>

        <link name="${name}_q">
            <!--xacro:dummy_inertial /-->

            <xacro:cylinder_inertial radius="0.008" length="0.028" mass="0.03">
                <origin xyz="0.008 0 0" rpy="0 1.57 0" />
            </xacro:cylinder_inertial>

            <visual>
                <geometry>
                    <mesh filename="package://schunk_svh_driver/description/meshes/f43.dae" />
                </geometry>
            </visual>
            <collision>
                <origin xyz="0.008 0 0" rpy="0 1.57 0" />
                <geometry>
                    <cylinder length="0.028" radius="0.008" />
                    <!--mesh filename="package://schunk_svh_driver/description/meshes/f43.dae" /-->
                </geometry>
            </collision>
        </link>

        <!-- Tip link and joint  -->
        <xacro:tip_ee name="${name}_pinky" parent="${name}_q" xyz="0.012 0.007 0.0"/>

        <joint name="${name}_Thumb_Flexion" type="revolute">
            <parent link="${name}_virtual_a" />
            <child link="${name}_a" />
            <limit effort="1000.0" lower="0.0" upper="0.9704" velocity="1" />
            <origin xyz="0 0 0" rpy="0 0 ${side*(-0.9704)}" />
            <axis xyz="0 0 ${side*(1)}" />
        </joint>

        <xacro:trans_xacro namehand="${name}" jointname="Thumb_Flexion"/>
            
        <!--transmission name="${name}_Thumb_Flexion_transmission">
            <type>transmission_interface/SimpleTransmission</type>
            <joint name="${name}_Thumb_Flexion">
                <hardwareInterface>EffortJointInterface</hardwareInterface>
            </joint>
            <actuator name="motor_${name}_Thumb_Flexion">
                <mechanicalReduction>1</mechanicalReduction>
                <hardwareInterface>EffortJointInterface</hardwareInterface>
            </actuator>
        </transmission-->

        <joint name="${name}_Thumb_Helper" type="fixed">
            <!--limit effort="1000" upper="0" lower="0" velocity="1"/-->
            <parent link="${name}_z" />
            <child link="${name}_virtual_a" />
            <origin xyz="0 0 0.04596" rpy="0 -1.5707 3.1416" />
        </joint>


        <!-- BASE_LINE JOINTS -->
        <joint name="${name}_Thumb_Opposition" type="revolute">
            <parent link="${name}_e1" />
            <child link="${name}_z" />
            <limit effort="1000.0" lower="0.0" upper="0.9879" velocity="1" />
            <origin xyz="${side*(-0.01690)} 0.02626 0" rpy="0 0.2618 1.571" />
            <axis xyz="0 0 ${side*(-1)}" />
        </joint>

        <xacro:trans_xacro namehand="${name}" jointname="Thumb_Opposition"/>


        <!-- JOINT NOT FOR BASE_LINE. BUT WRITTEN DOWN HERE FOR BETTER UX -->

        <joint name="${name}_f1" type="fixed">
            <!--limit effort="1000" upper="0" lower="0" velocity="1"/-->
            <parent link="${name}_e1" />
            <child link="${name}_d" />
            <origin xyz="0 0 0" rpy="0 0 0" />
        </joint>

        <joint name="${name}_f2" type="fixed">
            <!--limit effort="1000" upper="0" lower="0" velocity="1"/-->
            <parent link="${name}_d" />
            <child link="${name}_h" />
            <origin xyz="0 0 0" rpy="0 0 0" />
        </joint>

        <joint name="${name}_f3" type="fixed">
            <!--limit effort="1000" upper="0" lower="0" velocity="1"/-->
            <parent link="${name}_h" />
            <child link="${name}_d2" />
            <origin xyz="0 0 0" rpy="0 0 0" />
        </joint>

        <joint name="${name}_f4" type="fixed">
            <!--limit effort="1000" upper="0" lower="0" velocity="1"/-->
            <parent link="${name}_base_link" />
            <child link="${name}_e1" />
            <origin xyz="0 -0.01313 0" rpy="0 0 0" />
        </joint>

        <joint name="${name}_j5" type="revolute">
            <parent link="${name}_e1" />
            <child link="${name}_e2" />
            <limit effort="1000.0" lower="0.0" upper="0.98786" velocity="1" />
            <origin xyz="${side*(0.01840)} 0.006 0.0375" rpy="0 0 0" />
            <axis xyz="0 0 ${side*(1)}" />
            <mimic joint="${name}_Thumb_Opposition" multiplier="1" offset="0" />
        </joint>
        <xacro:trans_xacro namehand="${name}" jointname="j5"/>

        <joint name="${name}_f5" type="fixed">
            <!--limit effort="1000" upper="0" lower="0" velocity="1"/-->
            <parent link="${name}_e2" />
            <child link="${name}_e3" />
            <origin xyz="0 -0.0060 0" rpy="0 0 0" />
        </joint>

        <joint name="${name}_f6" type="fixed">
            <!--limit effort="1000" upper="0" lower="0" velocity="1"/-->
            <parent link="${name}_e3" />
            <child link="${name}_e" />
            <origin xyz="0 0 0" rpy="0 0 0" />
        </joint>

        <joint name="${name}_f7" type="fixed">
            <!--limit effort="1000" upper="0" lower="0" velocity="1"/-->
            <parent link="${name}_e" />
            <child link="${name}_e4" />
            <origin xyz="0 0 0" rpy="0 0 0" />
        </joint>

        <joint name="${name}_f8" type="fixed">
            <!--limit effort="1000" upper="0" lower="0" velocity="1"/-->
            <parent link="${name}_e" />
            <child link="${name}_e5" />
            <origin xyz="0 0 0" rpy="0 0 0" />
        </joint>

        <!-- THUMB JOINTS -->
        <joint name="${name}_j3" type="revolute">
            <parent link="${name}_a" />
            <child link="${name}_b" />
            <limit effort="1000.0" lower="0.0" upper="0.98506" velocity="1" />
            <origin xyz="0.0485 0 0" rpy="0 0 0" />
            <axis xyz="0 0 ${side*(1)}" />
            <mimic joint="${name}_Thumb_Flexion" multiplier="1.01511" offset="0" />
        </joint>
        <xacro:trans_xacro namehand="${name}" jointname="j3"/>

        <joint name="${name}_j4" type="revolute">
            <parent link="${name}_b" />
            <child link="${name}_c" />
            <limit effort="1000.0" lower="0.0" upper="1.406" velocity="1" />
            <origin xyz="0.030 0 0" rpy="0 0 0" />
            <axis xyz="0 0 ${side*(1)}" />
            <mimic joint="${name}_Thumb_Flexion" multiplier="1.44889" offset="0" />
        </joint>
        <xacro:trans_xacro namehand="${name}" jointname="j4"/>

        <!-- INDEX FINGER JOINTS -->
        <joint name="${name}_Index_Finger_Distal" type="revolute">
            <parent link="${name}_l" />
            <child link="${name}_p" />
            <limit effort="1000.0" lower="0" upper="1.334" velocity="1" />
            <origin xyz="0.04804 0 0" rpy="0 0 0" />
            <axis xyz="0 0 1" />
        </joint>
        <xacro:trans_xacro namehand="${name}" jointname="Index_Finger_Distal"/>

        
        <joint name="${name}_Index_Finger_Proximal" type="revolute">
            <parent link="${name}_virtual_l" />
            <child link="${name}_l" />
            <limit effort="1000.0" lower="0.0" upper="0.79849" velocity="1" />
            <origin xyz="0 0 0" rpy="-1.5707 0 0" />
            <axis xyz="0 0 1" />
        </joint>
        <xacro:trans_xacro namehand="${name}" jointname="Index_Finger_Proximal"/>

        <!-- JOINT Finger_Spread in BASE_LINE section for better UX -->
        <joint name="${name}_j14" type="revolute">
            <parent link="${name}_p" />
            <child link="${name}_t" />
            <limit effort="1000.0" lower="0" upper="1.394" velocity="1" />
            <origin xyz="0.026 0 0" rpy="0 0 0" />
            <axis xyz="0 0 1" />
            <mimic joint="${name}_Index_Finger_Distal" multiplier="1.0450" offset="0" />
        </joint>
        <xacro:trans_xacro namehand="${name}" jointname="j14"/>

        <!-- MIDDLE FINGER JOINTS -->
        <joint name="${name}_Middle_Finger_Proximal" type="revolute">
            <parent link="${name}_virtual_k" />
            <child link="${name}_k" />
            <limit effort="1000.0" lower="0.0" upper="0.79849" velocity="1" />
            <origin xyz="0 0 0" rpy="-1.5707 0 0" />
            <axis xyz="0 0 1" />
        </joint>
        <xacro:trans_xacro namehand="${name}" jointname="Middle_Finger_Proximal"/>

        <joint name="${name}_Middle_Finger_Distal" type="revolute">
            <parent link="${name}_k" />
            <child link="${name}_o" />
            <limit effort="1000.0" lower="0" upper="1.334" velocity="1" />
            <origin xyz="0.05004 0 0" rpy="0 0 0" />
            <axis xyz="0 0 1" />
        </joint>
        <xacro:trans_xacro namehand="${name}" jointname="Middle_Finger_Distal"/>

        <joint name="${name}_j15" type="revolute">
            <parent link="${name}_o" />
            <child link="${name}_s" />
            <limit effort="1000.0" lower="0" upper="1.334" velocity="1" />
            <origin xyz="0.032 0 0" rpy="0 0 0" />
            <axis xyz="0 0 1" />
            <mimic joint="${name}_Middle_Finger_Distal" multiplier="1.0454" offset="0" />
        </joint>
        <xacro:trans_xacro namehand="${name}" jointname="j15"/>

        <!-- RING FINGER JOINTS -->
        <joint name="${name}_Ring_Finger" type="revolute">
            <parent link="${name}_virtual_j" />
            <child link="${name}_j" />
            <limit effort="1000.0" lower="0.0" upper="0.98175" velocity="1" />
            <origin xyz="0 0 0" rpy="1.5707 0 0" />
            <axis xyz="0 0 1" />
        </joint>
        <xacro:trans_xacro namehand="${name}" jointname="Ring_Finger"/>


        <joint name="${name}_j12" type="revolute">
            <parent link="${name}_j" />
            <child link="${name}_n" />
            <limit effort="1000.0" lower="0" upper="1.334" velocity="1" />
            <origin xyz="0.05004 0 0" rpy="0 0 0" />
            <axis xyz="0 0 1" />
            <mimic joint="${name}_Ring_Finger" multiplier="1.3588" offset="0" />
        </joint>
        <xacro:trans_xacro namehand="${name}" jointname="j12"/>

        <joint name="${name}_j16" type="revolute">
            <parent link="${name}_n" />
            <child link="${name}_r" />
            <limit effort="1000.0" lower="0" upper="1.395" velocity="1" />
            <origin xyz="0.032 0 0" rpy="0 0 0" />
            <axis xyz="0 0 1" />
            <mimic joint="${name}_Ring_Finger" multiplier="1.42093" offset="0" />
        </joint>
        <xacro:trans_xacro namehand="${name}" jointname="j16"/>

        <!-- PINKY JOINTS -->
        <joint name="${name}_Pinky" type="revolute">
            <parent link="${name}_virtual_i" />
            <child link="${name}_i" />
            <limit effort="1000.0" lower="0.0" upper="0.98175" velocity="1" />
            <origin xyz="0 0 0" rpy="1.5707 0 0" />
            <axis xyz="0 0 1" />
        </joint>
        <xacro:trans_xacro namehand="${name}" jointname="Pinky"/>

        <joint name="${name}_j13" type="revolute">
            <parent link="${name}_i" />
            <child link="${name}_m" />
            <limit effort="1000.0" lower="0" upper="1.334" velocity="1" />
            <origin xyz="0.04454 0 0" rpy="0 0 0" />
            <axis xyz="0 0 1" />
            <mimic joint="${name}_Pinky" multiplier="1.35880" offset="0" />
        </joint>
        <xacro:trans_xacro namehand="${name}" jointname="j13"/>

        <joint name="${name}_j17" type="revolute">
            <parent link="${name}_m" />
            <child link="${name}_q" />
            <limit effort="1000.0" lower="0" upper="1.3971" velocity="1" />
            <origin xyz="0.022 0 0" rpy="0 0 0" />
            <axis xyz="0 0 1" />
            <mimic joint="${name}_Pinky" multiplier="1.42307" offset="0" />
        </joint>
        <xacro:trans_xacro namehand="${name}" jointname="j17"/>

        <joint name="${name}_index_spread" type="revolute">
            <parent link="${name}_d2" />
            <child link="${name}_virtual_l" />
            <limit effort="1000.0" lower="0.0" upper="0.28833" velocity="1" />
            <origin xyz="${side*(-0.025)} 0 0.110" rpy="0 -1.5707 1.5707" />
            <axis xyz="0 0 ${side*(1)}" />
            <mimic joint="${name}_Finger_Spread" multiplier="0.5" offset="0" />
        </joint>
        <xacro:trans_xacro namehand="${name}" jointname="index_spread"/>

        <joint name="${name}_middle_spread_dummy" type="fixed">
            <!--limit effort="1000" upper="0" lower="0" velocity="1"/-->
            <parent link="${name}_d" />
            <child link="${name}_virtual_k" />
            <origin xyz="0 0 0.110" rpy="0 -1.5707 1.5707" />
        </joint>


        <joint name="${name}_ring_spread" type="revolute">
            <parent link="${name}_e5" />
            <child link="${name}_virtual_j" />
            <limit effort="1000.0" lower="0.0" upper="0.28833" velocity="1" />
            <origin xyz="${side*(0.003855)} 0 0.0655" rpy="-1.5707 -1.5707 0" />
            <axis xyz="0 0 ${side*(1)}" />
            <mimic joint="${name}_Finger_Spread" multiplier="0.5" offset="0" />
        </joint>
        <xacro:trans_xacro namehand="${name}" jointname="ring_spread"/>

        <joint name="${name}_Finger_Spread" type="revolute">
            <parent link="${name}_e4" />
            <child link="${name}_virtual_i" />
            <limit effort="1000.0" lower="0.00" upper="0.5829" velocity="1" />
            <origin xyz="${side*(0.025355)} 0 0.056" rpy="-1.5707 -1.5707 0" />
            <axis xyz="0 0 ${side*(1)}" />
        </joint>    
        <xacro:trans_xacro namehand="${name}" jointname="Finger_Spread"/>

        <!-- Gazebo contact properties of the links that can have contact with objects -->
        <xacro:gazebo_contact link_name="right_hand_c" />
        <xacro:gazebo_contact link_name="right_hand_b" />
        <xacro:gazebo_contact link_name="right_hand_a" />
        <xacro:gazebo_contact link_name="right_hand_t" />
        <xacro:gazebo_contact link_name="right_hand_p" />
        <xacro:gazebo_contact link_name="right_hand_l" />
        <xacro:gazebo_contact link_name="right_hand_s" />
        <xacro:gazebo_contact link_name="right_hand_o" />
        <xacro:gazebo_contact link_name="right_hand_k" />
        <xacro:gazebo_contact link_name="right_hand_r" />
        <xacro:gazebo_contact link_name="right_hand_n" />
        <xacro:gazebo_contact link_name="right_hand_j" />
        <xacro:gazebo_contact link_name="right_hand_q" />
        <xacro:gazebo_contact link_name="right_hand_m" />
        <xacro:gazebo_contact link_name="right_hand_i" />
        
        <xacro:gazebo_contact link_name="right_hand_d" />

    </xacro:macro>




        <property name="deg_to_rad" value="0.01745329251994329577"/>

    <property name="M_SCALE" value="0.001 0.001 0.001"/> 
    <property name="M_PI" value="3.14159"/>

    <property name="radious" value="0.02" />

    <xacro:macro name="inertial_matrix" params="mass">
      <inertial>
        <mass value="${mass}" />
        <inertia ixx="1.0" ixy="0.0" ixz="0.0" iyy="0.5" iyz="0.0" izz="1.0" />
      </inertial>
    </xacro:macro>

   <xacro:macro name="transmission_block" params="joint_name">
      <transmission name="${joint_name}_transmission">
        <type>transmission_interface/SimpleTransmission</type>
        <joint name="${joint_name}">
          <hardwareInterface>EffortJointInterface</hardwareInterface>
        </joint>
        <actuator name="${joint_name}_motor">
          <hardwareInterface>EffortJointInterface</hardwareInterface>
          <mechanicalReduction>100</mechanicalReduction>
        </actuator>
      </transmission>
   </xacro:macro>

    <property name="link1_alpha" value="${-M_PI/2}" />
    <property name="link1_d" value="0.0001" />
    <property name="link1_a" value="0" />

    <property name="link2_alpha" value="${M_PI/2}" />
    <property name="link2_d" value="0" />
    <property name="link2_a" value="0" />

    <property name="link3_alpha" value="${-M_PI/2}" />
    <property name="link3_d" value="1" />
    <property name="link3_a" value="0" />

    <property name="link4_alpha" value="${M_PI/2}" />
    <property name="link4_d" value="0" />
    <property name="link4_a" value="0" />

    <property name="link5_alpha" value="${M_PI/2}" />
    <property name="link5_d" value="1" />
    <property name="link5_a" value="0" />

    <property name="link6_alpha" value="${-M_PI/2}" />
    <property name="link6_d" value="0" />
    <property name="link6_a" value="0" />

    <property name="link7_alpha" value="${M_PI/2}" />
    <property name="link7_d" value="1" />
    <property name="link7_a" value="0" />

    <property name="box_size" value="0.001" />


    
    <!-- Anthropomorphic Arm -->

<!--
     <link name="world2"/> 
-->
    <joint name="fixed to arm" type="fixed">
        <parent link="world" />
        <child link = "link1" />
        <origin xyz="0 0 0" rpy="0 0 0" />
    </joint>

     <link name="link1">
    <visual>
      <origin rpy="0 0 0" xyz="0 0 0.001"/>
      <geometry>
        <box size="0.1 0.1  0.01"/>
      </geometry>
      <material name="Red"/>
    </visual>
    <inertial>
      <mass value="1"/>
      <inertia ixx="1.0" ixy="0.0" ixz="0.0" iyy="0.5" iyz="0.0" izz="1.0"/>
    </inertial>
  </link>

    <joint name="my_joint_1" type="revolute">
        <parent link="link1"/>
        <child link="my_link1"/>
        <origin xyz="0.00001    0.00001 0.01" rpy="0 0 0" />
        <axis xyz="0 0 1" />
        <limit effort="1000" velocity="1000" lower="${-M_PI}" upper="${M_PI}"/>
    </joint>


    <link name="my_link1" >
        <visual>
            <origin xyz="0.0001 0.0001  ${link1_d/2}" rpy="0 0 0" />
            <geometry>
                <cylinder radius="${radious}" length="${link1_d}"/>
            </geometry>
            <material name="Red" />
        </visual>
        <xacro:inertial_matrix mass = "0.0001"/>

    </link>


    <joint name="my_joint_2" type="revolute">
        <parent link="my_link1"/>
        <child link="my_link2"/>
        <origin xyz="0 0 ${link1_d}" rpy="${link1_alpha} 0 0" />
        <axis xyz="0 0 1" />
        <limit effort="1000" velocity="1000" lower="${-M_PI}" upper="${M_PI}"/>
    </joint>

    <link name="my_link2" >
        <visual>
            <origin xyz="0 0 0" rpy="0 0 0" />
            <geometry>
                <box size="${box_size} ${box_size} ${box_size}" />
            </geometry>
            <material name="Red" />
        </visual>
        <xacro:inertial_matrix mass = "0.0001"/>

    </link>

      <gazebo reference="my_link2">
    <material>Gazebo/White</material>
  </gazebo>

    <joint name="my_joint_3" type="revolute">
        <parent link="my_link2"/>
        <child link="my_link3"/>
        <origin xyz="0 0 0" rpy="${link2_alpha} 0 0" />
        <axis xyz="0 0 1" />
        <limit effort="1000" velocity="1000" lower="${-M_PI}" upper="${M_PI}"/>
    </joint>

    <link name="my_link3" >
        <visual>
            <origin xyz="0 0 ${link3_d/2}" rpy="0 0 0" />
            <geometry>
                <cylinder radius="${radious}" length="${link3_d}"/>
            </geometry>
            <material name="Red" />
        </visual>
        <collision>
            <origin xyz="0 0 ${link3_d/2}" rpy="0 0 0" />
            <geometry>
                <cylinder radius="${radious}" length="${link3_d}"/>
            </geometry>
        </collision>
        <xacro:inertial_matrix mass="1"/>
    </link>

      <gazebo reference="my_link3">
    <material>Gazebo/White</material>
  </gazebo>

    <joint name="my_joint_4" type="revolute">
        <parent link="my_link3"/>
        <child link="my_link4"/>
        <origin xyz="0 0 ${link3_d}" rpy="${link3_alpha} 0 0" />
        <axis xyz="0 0 1" />
        <limit effort="1000" velocity="1000" lower="${-M_PI}" upper="${M_PI}"/>
    </joint>

    <link name="my_link4" >
        <visual>
            <origin xyz="0 0 0" rpy="0 0 0" />
            <geometry>
                <box size="${box_size} ${box_size} ${box_size}" />
            </geometry>
            <material name="Red" />
        </visual>
        <xacro:inertial_matrix mass = "0.00001"/>

    </link>

      <gazebo reference="my_link4">
    <material>Gazebo/White</material>
  </gazebo>

    <joint name="my_joint_5" type="revolute">
        <parent link="my_link4"/>
        <child link="my_link5"/>
        <origin xyz="0 0 0" rpy="${link4_alpha} 0 0" />
        <axis xyz="0 0 1" />
        <limit effort="1000" velocity="1000" lower="${-M_PI}" upper="${M_PI}"/>
    </joint>

    <link name="my_link5" >
        <visual>
            <origin xyz="0 0 ${link5_d/2}" rpy="0 0 0" />
            <geometry>
                <cylinder radius="${radious}" length="${link5_d}"/>
            </geometry>
            <material name="Red" />
        </visual>
        <collision>
            <origin xyz="0 0 ${link5_d/2}" rpy="0 0 0" />
            <geometry>
                <cylinder radius="${radious}" length="${link5_d}"/>
            </geometry>
        </collision>
        <xacro:inertial_matrix mass="1"/>
    </link>

      <gazebo reference="my_link5">
    <material>Gazebo/White</material>
  </gazebo>

    <joint name="my_joint_6" type="revolute">
        <parent link="my_link5"/>
        <child link="my_link6"/>
        <origin xyz="0 0 ${link5_d}" rpy="${link5_alpha} 0 0" />
        <axis xyz="0 0 1" />
        <limit effort="1000" velocity="1000" lower="${-M_PI}" upper="${M_PI}"/>
    </joint>

    <link name="my_link6" >
        <visual>
            <origin xyz="0 0 0" rpy="0 0 0" />
            <geometry>
                <box size="${box_size} ${box_size} ${box_size}" />
            </geometry>
            <material name="Red" />
        </visual>
        <xacro:inertial_matrix mass="0.0001"/>

    </link>

  <gazebo reference="my_link6">
    <material>Gazebo/White</material>
  </gazebo>

    <joint name="my_joint_7" type="revolute">
        <parent link="my_link6"/>
        <child link="my_link7"/>
        <origin xyz="0 0 ${link6_d}" rpy="${link6_alpha} 0 0" />
        <axis xyz="0 0 1" />
        <limit effort="1000" velocity="1000" lower="${-M_PI}" upper="${M_PI}"/>

    </joint>

    <link name="my_link7" >
        <visual>
            <origin xyz="0 0 ${link7_d/2}" rpy="0 0 0" />
            <geometry>
                <cylinder radius="${radious}" length="${link7_d}"/>
            </geometry>
            <material name="Red" />
        </visual>
        <collision>
            <origin xyz="0 0 ${link7_d/2}" rpy="0 0 0" />
            <geometry>
                <cylinder radius="${radious}" length="${link7_d}"/>
            </geometry>
        </collision>
        <xacro:inertial_matrix mass="1"/>
    </link>

    <gazebo reference="my_link7">
        <material>Gazebo/White</material>
    </gazebo>


   <xacro:transmission_block joint_name="my_joint_1"/>    
   <xacro:transmission_block joint_name="my_joint_2"/>
   <xacro:transmission_block joint_name="my_joint_3"/>
   <xacro:transmission_block joint_name="my_joint_4"/>
   <xacro:transmission_block joint_name="my_joint_5"/>
   <xacro:transmission_block joint_name="my_joint_6"/>
   <xacro:transmission_block joint_name="my_joint_7"/>

<gazebo>
    <plugin name="p3d_base_controller" filename="libgazebo_ros_p3d.so">
    <alwaysOn>true</alwaysOn>
    <updateRate>100.0</updateRate>
    <bodyName>my_link7</bodyName>
    <topicName>base_pose_ground_truth</topicName>
    <gaussianNoise>0</gaussianNoise>
    <frameName>map</frameName>
    <xyzOffsets>0 0 0</xyzOffsets> 
    <rpyOffsets>0 0 0</rpyOffsets>
   <!-- <interface:position name="p3d_base_position"/>-->
  </plugin>
</gazebo>

</robot>

